Workbook

Sheet Import_Master
A1: Nazev | B1: Kategorie | C1: ELKOV_MJ | D1: ELKOV_Kod | E1: ELKOV_Nazev | F1: ELKOV_Cena | G1: ELKOV_Měna | H1: EMAS_MJ | I1: EMAS_Kod | J1: EMAS_Nazev | K1: EMAS_Cena | L1: EMAS_Měna | M1: Poznamka
A2: CYKY-J 3x1,5 | B2: Kabel | C2: =_xlfn.XLOOKUP(E2, ELKOV!D:D, ELKOV!F:F, "chybí") -> m | D2: =_xlfn.XLOOKUP(E2, ELKOV!D:D, ELKOV!C:C, "chybí") -> 17018 | E2: Kabel CYKY-J 3x1,5 (C) | F2: =_xlfn.XLOOKUP(E2, ELKOV!D:D, ELKOV!G:G, "chybí") -> 23.22 | G2: =_xlfn.XLOOKUP(E2, ELKOV!D:D, ELKOV!H:H, "chybí") -> Kč | H2: =_xlfn.XLOOKUP(J2, EMAS!D:D, EMAS!F:F, "chybí") -> m | I2: =_xlfn.XLOOKUP(J2, EMAS!D:D, EMAS!C:C, "chybí") -> ELKAOS0802380 | J2: CYKY-J DCA 3 X 1,5 | K2: =_xlfn.XLOOKUP(J2, EMAS!D:D, EMAS!G:G, "chybí") -> 20.45 | L2: =_xlfn.XLOOKUP(J2, EMAS!D:D, EMAS!H:H, "chybí") -> Kč
A3: CYKY-J 3x2,5 | B3: Kabel | C3: =_xlfn.XLOOKUP(E3, ELKOV!D:D, ELKOV!F:F, "chybí") -> m | D3: =_xlfn.XLOOKUP(E3, ELKOV!D:D, ELKOV!C:C, "chybí") -> 17022 | E3: Kabel CYKY-J 3x2,5 (C) | F3: =_xlfn.XLOOKUP(E3, ELKOV!D:D, ELKOV!G:G, "chybí") -> 36.86 | G3: =_xlfn.XLOOKUP(E3, ELKOV!D:D, ELKOV!H:H, "chybí") -> Kč | H3: =_xlfn.XLOOKUP(J3, EMAS!D:D, EMAS!F:F, "chybí") -> m | I3: =_xlfn.XLOOKUP(J3, EMAS!D:D, EMAS!C:C, "chybí") -> ELKAOS0804150 | J3: CYKY-J DCA 3 X 2,5 | K3: =_xlfn.XLOOKUP(J3, EMAS!D:D, EMAS!G:G, "chybí") -> 33.59 | L3: =_xlfn.XLOOKUP(J3, EMAS!D:D, EMAS!H:H, "chybí") -> Kč
A4: CYKY-J 5x6 | B4: Kabel | C4: =_xlfn.XLOOKUP(E4, ELKOV!D:D, ELKOV!F:F, "chybí") -> m | D4: =_xlfn.XLOOKUP(E4, ELKOV!D:D, ELKOV!C:C, "chybí") -> 17062 | E4: Kabel CYKY-J 5x6 (C) | F4: =_xlfn.XLOOKUP(E4, ELKOV!D:D, ELKOV!G:G, "chybí") -> 151.73 | G4: =_xlfn.XLOOKUP(E4, ELKOV!D:D, ELKOV!H:H, "chybí") -> Kč | H4: =_xlfn.XLOOKUP(J4, EMAS!D:D, EMAS!F:F, "chybí") -> m | I4: =_xlfn.XLOOKUP(J4, EMAS!D:D, EMAS!C:C, "chybí") -> ELKASLJ560001 | J4: CYKY-J 5 X 6 | K4: =_xlfn.XLOOKUP(J4, EMAS!D:D, EMAS!G:G, "chybí") -> 126.33 | L4: =_xlfn.XLOOKUP(J4, EMAS!D:D, EMAS!H:H, "chybí") -> Kč
A5: Chránička optického kabelu | B5: Kabel | C5: =_xlfn.XLOOKUP(E5, ELKOV!D:D, ELKOV!F:F, "chybí") -> m | D5: =_xlfn.XLOOKUP(E5, ELKOV!D:D, ELKOV!C:C, "chybí") -> 41996059 | E5: Chránička optického kabelu KOPOS HDPE 06040 AS100 VO 40mm oranžová, svazek 100m | F5: =_xlfn.XLOOKUP(E5, ELKOV!D:D, ELKOV!G:G, "chybí") -> 81.17 | G5: =_xlfn.XLOOKUP(E5, ELKOV!D:D, ELKOV!H:H, "chybí") -> Kč | H5: =_xlfn.XLOOKUP(J5, EMAS!D:D, EMAS!F:F, "chybí") -> m | I5: =_xlfn.XLOOKUP(J5, EMAS!D:D, EMAS!C:C, "chybí") -> ELTUOH0494261 | J5: 06040 AS100 CHRANICKA OPT. KABELU oranz | K5: =_xlfn.XLOOKUP(J5, EMAS!D:D, EMAS!G:G, "chybí") -> 68.52 | L5: =_xlfn.XLOOKUP(J5, EMAS!D:D, EMAS!H:H, "chybí") -> Kč
A6: Krabice pod omítku | B6: Elektroinstalační materiál | C6: =_xlfn.XLOOKUP(E6, ELKOV!D:D, ELKOV!F:F, "chybí") -> ks | D6: =_xlfn.XLOOKUP(E6, ELKOV!D:D, ELKOV!C:C, "chybí") -> 83097261 | E6: KOPOS KRABICE UNIVERZÁLNÍ KU 68-45_KA | F6: =_xlfn.XLOOKUP(E6, ELKOV!D:D, ELKOV!G:G, "chybí") -> 9.33 | G6: =_xlfn.XLOOKUP(E6, ELKOV!D:D, ELKOV!H:H, "chybí") -> Kč | H6: =_xlfn.XLOOKUP(J6, EMAS!D:D, EMAS!F:F, "chybí") -> ks | I6: =_xlfn.XLOOKUP(J6, EMAS!D:D, EMAS!C:C, "chybí") -> ELOSOS1342603 | J6: KU 68-45_KA KRABICE UNIVERZALNI SEDA | K6: =_xlfn.XLOOKUP(J6, EMAS!D:D, EMAS!G:G, "chybí") -> 7.93 | L6: =_xlfn.XLOOKUP(J6, EMAS!D:D, EMAS!H:H, "chybí") -> Kč
A7: Spínač/Přepínač | B7: Spínače a zásuvky | C7: =_xlfn.XLOOKUP(E7, ELKOV!D:D, ELKOV!F:F, "chybí") -> ks | D7: =_xlfn.XLOOKUP(E7, ELKOV!D:D, ELKOV!C:C, "chybí") -> 81493004 | E7: Spínač Schneider Electric Asfora řazení 6, EPH0400121, 10A, bezšroubové svorky, bílá | F7: =_xlfn.XLOOKUP(E7, ELKOV!D:D, ELKOV!G:G, "chybí") -> 77.85 | G7: =_xlfn.XLOOKUP(E7, ELKOV!D:D, ELKOV!H:H, "chybí") -> Kč | H7: =_xlfn.XLOOKUP(J7, EMAS!D:D, EMAS!F:F, "chybí") -> ks | I7: =_xlfn.XLOOKUP(J7, EMAS!D:D, EMAS!C:C, "chybí") -> ELPRSP0601677 | J7: EPH0400121 Prepinac stridavy, r.6, bila | K7: =_xlfn.XLOOKUP(J7, EMAS!D:D, EMAS!G:G, "chybí") -> 63.32 | L7: =_xlfn.XLOOKUP(J7, EMAS!D:D, EMAS!H:H, "chybí") -> Kč
A8: Zásuvka | B8: Spínače a zásuvky | C8: =_xlfn.XLOOKUP(E8, ELKOV!D:D, ELKOV!F:F, "chybí") -> ks | D8: =_xlfn.XLOOKUP(E8, ELKOV!D:D, ELKOV!C:C, "chybí") -> 82696103 | E8: Zásuvka bezšroubová s clonkami Schneider Electric Sedna Design SDD111012, 230V, 16A, bílá | F8: =_xlfn.XLOOKUP(E8, ELKOV!D:D, ELKOV!G:G, "chybí") -> 110.62 | G8: =_xlfn.XLOOKUP(E8, ELKOV!D:D, ELKOV!H:H, "chybí") -> Kč | H8: =_xlfn.XLOOKUP(J8, EMAS!D:D, EMAS!F:F, "chybí") -> ks | I8: =_xlfn.XLOOKUP(J8, EMAS!D:D, EMAS!C:C, "chybí") -> ELOSOS0887627 | J8: SDD111012 Zasuvka bezsroubova bila | K8: =_xlfn.XLOOKUP(J8, EMAS!D:D, EMAS!G:G, "chybí") -> 91.29 | L8: =_xlfn.XLOOKUP(J8, EMAS!D:D, EMAS!H:H, "chybí") -> Kč
A9: Rozvaděč 4-modulový | B9: Skříně a rozvaděče | C9: =_xlfn.XLOOKUP(E9, ELKOV!D:D, ELKOV!F:F, "chybí") -> ks | D9: =_xlfn.XLOOKUP(E9, ELKOV!D:D, ELKOV!C:C, "chybí") -> 34989217 | E9: SPACE ROZVADĚČ RA 4 NA OM. | F9: =_xlfn.XLOOKUP(E9, ELKOV!D:D, ELKOV!G:G, "chybí") -> 223.5 | G9: =_xlfn.XLOOKUP(E9, ELKOV!D:D, ELKOV!H:H, "chybí") -> Kč | H9: =_xlfn.XLOOKUP(J9, EMAS!D:D, EMAS!F:F, "chybí") -> ks | I9: =_xlfn.XLOOKUP(J9, EMAS!D:D, EMAS!C:C, "chybí") -> ELROBY0441152 | J9: RA 4 Rozvadec na povrch (4M) IP30 plna | K9: =_xlfn.XLOOKUP(J9, EMAS!D:D, EMAS!G:G, "chybí") -> 192.4 | L9: =_xlfn.XLOOKUP(J9, EMAS!D:D, EMAS!H:H, "chybí") -> Kč
A10: Jistič 1-fázový | B10: Jističe | C10: =_xlfn.XLOOKUP(E10, ELKOV!D:D, ELKOV!F:F, "chybí") -> ks | D10: =_xlfn.XLOOKUP(E10, ELKOV!D:D, ELKOV!C:C, "chybí") -> 89800020 | E10: ABB JISTIČ S201-B20 1P 20A B 6KA | F10: =_xlfn.XLOOKUP(E10, ELKOV!D:D, ELKOV!G:G, "chybí") -> 166.86 | G10: =_xlfn.XLOOKUP(E10, ELKOV!D:D, ELKOV!H:H, "chybí") -> Kč | H10: =_xlfn.XLOOKUP(J10, EMAS!D:D, EMAS!F:F, "chybí") -> ks | I10: =_xlfn.XLOOKUP(J10, EMAS!D:D, EMAS!C:C, "chybí") -> ELPRJI0706884 | J10: S(Z)201-B20, 1 fazovy jistic, jmenovity | K10: =_xlfn.XLOOKUP(J10, EMAS!D:D, EMAS!G:G, "chybí") -> 146.02 | L10: =_xlfn.XLOOKUP(J10, EMAS!D:D, EMAS!H:H, "chybí") -> Kč
A11: Jistič 2-fázový | B11: Jističe | C11: =_xlfn.XLOOKUP(E11, ELKOV!D:D, ELKOV!F:F, "chybí") -> ks | D11: =_xlfn.XLOOKUP(E11, ELKOV!D:D, ELKOV!C:C, "chybí") -> 891901 | E11: ABB CHRÁNIČ PROUD. FH202 AC-40/0,03 2P 40A 30mA TYP AC 6KA | F11: =_xlfn.XLOOKUP(E11, ELKOV!D:D, ELKOV!G:G, "chybí") -> 605.24 | G11: =_xlfn.XLOOKUP(E11, ELKOV!D:D, ELKOV!H:H, "chybí") -> Kč | H11: =_xlfn.XLOOKUP(J11, EMAS!D:D, EMAS!F:F, "chybí") -> ks | I11: =_xlfn.XLOOKUP(J11, EMAS!D:D, EMAS!C:C, "chybí") -> ELOSOS0846527 | J11: FH202 A-40/0,03 2pol - A | K11: =_xlfn.XLOOKUP(J11, EMAS!D:D, EMAS!G:G, "chybí") -> 742.15 | L11: =_xlfn.XLOOKUP(J11, EMAS!D:D, EMAS!H:H, "chybí") -> Kč

Sheet ELKOV
A1: ID | B1: Dodavatel | C1: Kód | D1: Název | E1: Množství | F1: MJ | G1: Cena bez DPH | H1: Měna | I1: Komentář | J1: Cena bez DPH
A2: 1 | B2: ELKOV | C2: 17018 | D2: Kabel CYKY-J 3x1,5 (C) | E2: 1 | F2: m | G2: 23.22 | H2: Kč | J2: 23.22
A3: 2 | B3: ELKOV | C3: 17022 | D3: Kabel CYKY-J 3x2,5 (C) | E3: 1 | F3: m | G3: 36.86 | H3: Kč | J3: 36.86
A4: 3 | B4: ELKOV | C4: 17062 | D4: Kabel CYKY-J 5x6 (C) | E4: 1 | F4: m | G4: 151.73 | H4: Kč | J4: 151.73
A5: 4 | B5: ELKOV | C5: 41996059 | D5: Chránička optického kabelu KOPOS HDPE 06040 AS100 VO 40mm oranžová, svazek 100m | E5: 1 | F5: m | G5: 81.17 | H5: Kč | J5: 8117.00 | K5: za 100m
A6: 5 | B6: ELKOV | C6: 83097261 | D6: KOPOS KRABICE UNIVERZÁLNÍ KU 68-45_KA | E6: 1 | F6: ks | G6: 9.33 | H6: Kč | J6: 12298
A7: 6 | B7: ELKOV | C7: 81493004 | D7: Spínač Schneider Electric Asfora řazení 6, EPH0400121, 10A, bezšroubové svorky, bílá | E7: 1 | F7: ks | G7: 77.85 | H7: Kč | J7: 77.85
A8: 7 | B8: ELKOV | C8: 82696103 | D8: Zásuvka bezšroubová s clonkami Schneider Electric Sedna Design SDD111012, 230V, 16A, bílá | E8: 1 | F8: ks | G8: 110.62 | H8: Kč | J8: 110.62
A9: 8 | B9: ELKOV | C9: 34989217 | D9: SPACE ROZVADĚČ RA 4 NA OM. | E9: 1 | F9: ks | G9: 223.5 | H9: Kč | J9: 223.50
A10: 9 | B10: ELKOV | C10: 89800020 | D10: ABB JISTIČ S201-B20 1P 20A B 6KA | E10: 1 | F10: ks | G10: 166.86 | H10: Kč | J10: 166.86
A11: 10 | B11: ELKOV | C11: 891901 | D11: ABB CHRÁNIČ PROUD. FH202 AC-40/0,03 2P 40A 30mA TYP AC 6KA | E11: 1 | F11: ks | G11: 605.24 | H11: Kč | J11: 605.24

Sheet ELKOV.csv
A1: Kód | B1: Název | C1: Množství | D1: MJ | E1: Velikost balení | F1: Jednotková cena | G1: Měna | H1: Komentář
A2: 17022 | B2: Kabel CYKY-J 3x2,5 (C) | C2: 1 | D2: m | E2: 1 | F2: 36.86
A3: 17018 | B3: Kabel CYKY-J 3x1,5 (C) | C3: 1 | D3: m | E3: 1 | F3: 23.22
A4: 17062 | B4: Kabel CYKY-J 5x6 (C) | C4: 1 | D4: m | E4: 1 | F4: 151.73
A5: 34989217 | B5: SPACE ROZVADĚČ RA 4 NA OM. | C5: 1 | D5: ks | E5: 1 | F5: 223.50
A6: 89800020 | B6: ABB JISTIČ S201-B20 1P 20A B 6KA | C6: 1 | D6: ks | E6: 1 | F6: 166.86
A7: 891901 | B7: ABB CHRÁNIČ PROUD. FH202 AC-40/0,03 2P 40A 30mA TYP AC 6KA | C7: 1 | D7: ks | E7: 1 | F7: 605.24
A8: 82696103 | B8: Zásuvka bezšroubová s clonkami Schneider Electric Sedna Design SDD111012, 230V, 16A, bílá | C8: 1 | D8: ks | E8: 1 | F8: 110.62
A9: 81493004 | B9: Spínač Schneider Electric Asfora řazení 6, EPH0400121, 10A, bezšroubové svorky, bílá | C9: 1 | D9: ks | E9: 1 | F9: 77.85
A10: 83097261 | B10: KOPOS KRABICE UNIVERZÁLNÍ KU 68-45_KA | C10: 1 | D10: ks | E10: 1 | F10: 12298
A11: 41996059 | B11: Chránička optického kabelu KOPOS HDPE 06040 AS100 VO 40mm oranžová, svazek 100m | C11: 100 | D11: m | E11: 1 | F11: 8117.00

Sheet EMAS
A1: ID | B1: Dodavatel | C1: Kód | D1: Název | E1: Množství | F1: MJ | G1: Cena bez DPH | H1: Měna | I1: EAN | J1: Číslo zbo.dodavatele
A2: 1 | B2: EMAS | C2: ELKAOS0802380 | D2: CYKY-J DCA 3 X 1,5 | E2: 1 | F2: m | G2: 20.45 | H2: Kč | I2: 30 | J2: CYKY 3X1,5 DCA
A3: 2 | B3: EMAS | C3: ELKAOS0804150 | D3: CYKY-J DCA 3 X 2,5 | E3: 1 | F3: m | G3: 33.59 | H3: Kč | I3: 10 | J3: CYKY-J DCA 3 X 2,5
A4: 3 | B4: EMAS | C4: ELKASLJ560001 | D4: CYKY-J 5 X 6 | E4: 1 | F4: m | G4: 126.33 | H4: Kč | I4: 3554670000000 | J4: CYKY 5X6
A5: 4 | B5: EMAS | C5: ELTUOH0494261 | D5: 06040 AS100 CHRANICKA OPT. KABELU oranz | E5: 1 | F5: m | G5: 68.52 | H5: Kč | I5: 8595060000000 | J5: 06040_AS100
A6: 5 | B6: EMAS | C6: ELOSOS1342603 | D6: KU 68-45_KA KRABICE UNIVERZALNI SEDA | E6: 1 | F6: ks | G6: 7.93 | H6: Kč | I6: 8595570000000 | J6: KU 68-45_KA
A7: 6 | B7: EMAS | C7: ELPRSP0601677 | D7: EPH0400121 Prepinac stridavy, r.6, bila | E7: 1 | F7: ks | G7: 63.32 | H7: Kč | I7: 3606480000000 | J7: EPH0400121
A8: 7 | B8: EMAS | C8: ELOSOS0887627 | D8: SDD111012 Zasuvka bezsroubova bila | E8: 1 | F8: ks | G8: 91.29 | H8: Kč | I8: 3606480000000 | J8: SDD111012
A9: 8 | B9: EMAS | C9: ELROBY0441152 | D9: RA 4 Rozvadec na povrch (4M) IP30 plna | E9: 1 | F9: ks | G9: 192.4 | H9: Kč | I9: 8595170000000 | J9: RA 4
A10: 9 | B10: EMAS | C10: ELPRJI0706884 | D10: S(Z)201-B20, 1 fazovy jistic, jmenovity | E10: 1 | F10: ks | G10: 146.02 | H10: Kč | I10: 4016780000000 | J10: 2CDS251001R0205
A11: 10 | B11: EMAS | C11: ELOSOS0846527 | D11: FH202 A-40/0,03 2pol - A | E11: 1 | F11: ks | G11: 742.15 | H11: Kč | I11: 8012540000000 | J11: 2CSF202102R1400

Sheet EMAS.csv
A1: Ceny jsou platné od 22.06.2026 do 29.06.2026 nebo do vyprodání zásob.
A2: SAP | B2: Název | C2: EAN | D2: Číslo zbo.dodavatele | E2: OMJ | F2: Cena bez DPH | G2: Měna
A3: ELROBY0441152 | B3: RA 4 Rozvadec na povrch (4M) IP30 plna | C3: 8595170000000 | D3: RA 4 | E3: KS | F3: 192.4 | G3: Kč
A4: ELTUOH0494261 | B4: 06040 AS100 CHRANICKA OPT. KABELU oranz | C4: 8595060000000 | D4: 06040_AS100 | E4: M | F4: 68.52 | G4: Kč
A5: ELPRSP0601677 | B5: EPH0400121 Prepinac stridavy, r.6, bila | C5: 3606480000000 | D5: EPH0400121 | E5: KS | F5: 63.32 | G5: Kč
A6: ELPRJI0706884 | B6: S(Z)201-B20, 1 fazovy jistic, jmenovity | C6: 4016780000000 | D6: 2CDS251001R0205 | E6: KS | F6: 146.02 | G6: Kč
A7: ELOSOS0846527 | B7: FH202 A-40/0,03 2pol - A | C7: 8012540000000 | D7: 2CSF202102R1400 | E7: KS | F7: 742.15 | G7: Kč
A8: ELOSOS0887627 | B8: SDD111012 Zasuvka bezsroubova bila | C8: 3606480000000 | D8: SDD111012 | E8: KS | F8: 91.29 | G8: Kč
A9: ELOSOS1342603 | B9: KU 68-45_KA KRABICE UNIVERZALNI SEDA | C9: 8595570000000 | D9: KU 68-45_KA | E9: KS | F9: 7.93 | G9: Kč
A10: ELKASLJ560001 | B10: CYKY-J 5 X 6 | C10: 3554670000000 | D10: CYKY 5X6 | E10: M | F10: 126.33 | G10: Kč
A11: ELKAOS0804150 | B11: CYKY-J DCA 3 X 2,5 | C11: 10 | D11: CYKY-J DCA 3 X 2,5 | E11: M | F11: 33.59 | G11: Kč
A12: ELKAOS0802380 | B12: CYKY-J DCA 3 X 1,5 | C12: 30 | D12: CYKY 3X1,5 DCA | E12: M | F12: 20.45 | G12: Kč

Sheet EMAS.csv - ALL
A1: Ceny jsou platné od 22.06.2026 do 29.06.2026 nebo do vyprodání zásob.
A2: SAP | B2: Název | C2: EAN | D2: Číslo zbo.dodavatele | E2: OMJ | F2: Cena bez DPH | G2: Měna
A3: ELTEDO0000441 | B3: 1145/54 Instalacni krabice, 4 moduly | C3: 8021160000000 | D3: 1145/54 | E3: KS | F3: 432.26 | G3: Kč
A4: ELTEDO0000437 | B4: 1145/500 Hlasova jednotka | C4: 8021160000000 | D4: 1145/500 | E4: KS | F4: 769.77 | G4: Kč
A5: ELTEDO0000438 | B5: 1145/51 Instalacni krabice, 1 modul | C5: 8021160000000 | D5: 1145/51 | E5: KS | F5: 160.67 | G5: Kč
A6: ELTEDO0000439 | B6: 1145/52 Instalacni krabice, 2 moduly | C6: 8021160000000 | D6: 1145/52 | E6: KS | F6: 242.56 | G6: Kč
A7: ELTEDO0000440 | B7: 1145/53 Instalacni krabice, 3 moduly | C7: 8021160000000 | D7: 1145/53 | E7: KS | F7: 272.63 | G7: Kč
A8: ELTEDO0000732 | B8: 9000/230 Zdroj 230 V, 18 VA,3 DIN moduly | C8: 8021160000000 | D8: 9000/230 | E8: KS | F8: 541.11 | G8: Kč
A9: ELTEDO0000709 | B9: 786/11 Zdroj 230V, 28VA | C9: 8021160000000 | D9: 786/11 | E9: KS | F9: 1673.89 | G9: Kč
A10: ELTEDO0000113 | B10: 64090 tlac. KKO 2001WS/WS, bile | C10: 4011460000000 | D10: 64090 | E10: KS | F10: 204.21 | G10: Kč
A11: ELZVPR0000033 | B11: 31053 Houkacka 631 24V DC 0,04A(96dB/A) | C11: 4011460000000 | D11: 31053 | E11: KS | F11: 1078.06 | G11: Kč
A12: ELZVPR0000036 | B12: 31371 Houkacka se svetel.signal.WL6301 | C12: 4011460000000 | D12: 31371 | E12: KS | F12: 2175.82 | G12: Kč
A13: ELZVPR0000028 | B13: 24091 Zvonek LTW 3371A 230V WS | C13: 4011460000000 | D13: 24091 | E13: KS | F13: 569.09 | G13: Kč
A14: ELZVPR0000030 | B14: 31043 Houkacka 630 24V AC 0,2A (92dB/A) | C14: 4011460000000 | D14: 31043 | E14: KS | F14: 1003.43 | G14: Kč
A15: ELZVPR0000031 | B15: 31047 Houkacka 630 240V 0,02A(92dB/A) | C15: 4011460000000 | D15: 31047 | E15: KS | F15: 872.82 | G15: Kč
A16: ELZVPR0000025 | B16: 24075 Zvonek LTW 1101A 8V WS | C16: 4011460000000 | D16: 24075 | E16: KS | F16: 242.56 | G16: Kč
A17: ELZVPR0000084 | B17: 44179 Elektronicky gong 569, ~230V | C17: 4011460000000 | D17: 44179 | E17: KS | F17: 388.31 | G17: Kč
A18: ELTEDO0000090 | B18: 51011 Tlacitko MONTILUX | C18: 4011460000000 | D18: 51011 | E18: KS | F18: 272.63 | G18: Kč
A19: ELTEDO0000091 | B19: 51013 Tlacitko COMBIFIX ETA 2121 | C19: 4011460000000 | D19: 51013 | E19: KS | F19: 243.6 | G19: Kč
A20: ELTEDO0000092 | B20: 51014 Tlacitko COMBIFIX II ETA 2122 | C20: 4011460000000 | D20: 51014 | E20: KS | F20: 243.6 | G20: Kč
A21: ELZVPR0000087 | B21: 44665 Elektromechanicky gong 665 | C21: 4011460000000 | D21: 44665 | E21: KS | F21: 550.01 | G21: Kč
A22: ELTEDO0000382 | B22: 1150/1 Elektron.domov.telefon s tl.odem. | C22: 8021160000000 | D22: 1150/1 | E22: KS | F22: 617.39 | G22: Kč
A23: ELTEDO0000378 | B23: 1132/53 Modul nastav.hlasitost.vyzvaneni | C23: 8021160000000 | D23: 1132/53 | E23: KS | F23: 204.21 | G23: Kč
A24: ELTEDO0000361 | B24: 1128/500 Hlasova jedn. do panelu 1129 | C24: 8021160000000 | D24: 1128/500 | E24: KS | F24: 588.37 | G24: Kč
A25: ELPONO0002867 | B25: PNA3 250A gG nozova poj. vlozka, vel. 3 | C25: 8590130000000 | D25: OEZ:40358 | E25: KS | F25: 373.33 | G25: Kč
A26: ELPONO0002865 | B26: PNA3 200A gG nozova poj. vlozka, vel. 3 | C26: 8590130000000 | D26: OEZ:40356 | E26: KS | F26: 391.52 | G26: Kč
A27: ELPONO0002859 | B27: PNA2 315A gG nozova poj. vlozka, vel. 2 | C27: 8590130000000 | D27: OEZ:40397 | E27: KS | F27: 277.2 | G27: Kč
A28: ELPONO0002860 | B28: PNA2 350A gG nozova poj. vlozka, vel. 2 | C28: 8590130000000 | D28: OEZ:40398 | E28: KS | F28: 292.61 | G28: Kč
A29: ELPONO0002861 | B29: PNA2 400A gG nozova poj. vlozka, vel. 2 | C29: 8590130000000 | D29: OEZ:40399 | E29: KS | F29: 292.61 | G29: Kč
A30: ELPONO0002868 | B30: PNA3 315A gG nozova poj. vlozka, vel. 3 | C30: 8590130000000 | D30: OEZ:40359 | E30: KS | F30: 373.33 | G30: Kč
A31: ELPONO0002857 | B31: PNA2 224A gG nozova poj. vlozka, vel. 2 | C31: 8590130000000 | D31: OEZ:40395 | E31: KS | F31: 238.26 | G31: Kč
A32: ELPONO0002858 | B32: PNA2 250A gG nozova poj. vlozka, vel. 2 | C32: 8590130000000 | D32: OEZ:40396 | E32: KS | F32: 238.26 | G32: Kč
A33: ELPONO0002844 | B33: PNA1 160A gG nozova poj. vlozka, vel. 1 | C33: 8590130000000 | D33: OEZ:40439 | E33: KS | F33: 131.36 | G33: Kč
... A261: ELKAPS0075609 | B261: spona pro nerez pasy C953 s. 9,53mm | C261: 8595060000000 | D261: PTH-SC9-C953 | E261: KS | F261: 5.92 | G261: Kč
A262: ELZLZE0078495 | B262: kloubove spojeni Kz 60 | C262: 8595590000000 | D262: 3100803 | E262: KS | F262: 104.17 | G262: Kč
A263: ELZLZE0078542 | B263: konzola 300 | C263: 8595590000000 | D263: 4010408 | E263: KS | F263: 130.84 | G263: Kč
A264: ELZLZE0078544 | B264: konzola 500 | C264: 8595590000000 | D264: 4010410 | E264: KS | F264: 210.34 | G264: Kč
A265: ELKAOS0078452 | B265: SONAP 28 kabelova prichytka C | C265: 8595590000000 | D265: 5100302 | E265: KS | F265: 34.29 | G265: Kč
A266: ELKAOS0078451 | B266: SONAP 18 kabelova prichytka C | C266: 8595590000000 | D266: 5100301 | E266: KS | F266: 29.68 | G266: Kč
A267: ELKAOS0078456 | B267: SONAP 90 | C267: 8595590000000 | D267: 5100306 | E267: KS | F267: 102.08 | G267: Kč
...

Sheet EMAS.xls
A1: Č. položky | B1: zboží | C1: název produktu | D1: objednací číslo | E1: množství | F1: typ položky | G1: prodejní cena | H1: nákupní cena | I1: dodavatel | J1: MPN | K1: Cena za kus (bez DPH) | L1: Hodnota RP | M1: Cena celkem (bez DPH)
A2: 10 | B2: ELKAOS0804150 | C2: CYKY-J DCA 3 X 2,5 | E2: 1 | J2: CYKY-J DCA 3 X 2,5 | K2: 33.59 | L2: 0 | M2: 33.59
A3: 20 | C3: Poplatek za střih | E3: 1 | K3: 500 | L3: 0 | M3: 500
A4: 30 | B4: ELKAOS0802380 | C4: CYKY-J DCA 3 X 1,5 | E4: 1 | J4: CYKY 3X1,5 DCA | K4: 20.45 | L4: 0 | M4: 20.45
A5: 40 | C5: Poplatek za střih | E5: 1 | K5: 500 | L5: 0 | M5: 500
A6: 50 | B6: ELKASLJ560001 | C6: Silový kabel pevný CYKY-J 5 X 6 | E6: 1 | J6: CYKY 5X6 | K6: 126.33 | L6: 0 | M6: 126.33
A7: 60 | B7: ELROBY0441152 | C7: Rozváděč na povrch 4 moduly SPACE IP30, okénko plné, bílá N.G. ELEKTRO RA 4 | E7: 1 | J7: RA 4 | K7: 192.4 | L7: 0 | M7: 192.4
A8: 70 | B8: ELPRJI0706884 | C8: S201-B20 1 fázový jistič 20 A char. B 6 kA ABB 2CDS251001R0205 | E8: 1 | J8: 2CDS251001R0205 | K8: 146.02 | L8: 0.12 | M8: 146.02
A9: 80 | B9: ELOSOS0846527 | C9: FH202 A-40/0,03 proudový chránič dvojpólový 40 A 30mA A ABB 2CSF202102R1400 | E9: 1 | J9: 2CSF202102R1400 | K9: 742.15 | L9: 0.2 | M9: 742.15
A10: 90 | B10: ELOSOS0887627 | C10: Sedna D/E Zásuvka 230V 16A clonky bezšroubová, Bílá SCHNEIDER SDD111012 | E10: 1 | J10: SDD111012 | K10: 91.29 | L10: 0 | M10: 91.29
A11: 100 | B11: ELPRSP0601677 | C11: ASFORA Přepínač střídavý řazení 6, bezšroubový, bílá SCHNEIDER EPH0400121 | E11: 1 | J11: EPH0400121 | K11: 63.32 | L11: 0 | M11: 63.32
A12: 110 | B12: ELOSOS1342603 | C12: KRABICE UNIVERZÁLNÍ, konfigurace KA, barva šedá KOPOS KU 68-45_KA | E12: 1 | J12: KU 68-45_KA | K12: 7.93 | L12: 0 | M12: 7.93
A13: 120 | B13: ELTUOH0494261 | C13: Chránička optického kabelu HDPE bezhalogenová pr. 40 mm, 750N/20cm, oranžová | E13: 100 | J13: 06040_AS100 | K13: 68.52 | L13: 0 | M13: 6852
M15: -93.22 | N15: Sleva na nákup 1%
M16: 9182.26 | N16: bez DPH
M17: 11111 | N17: s DPH
